2025-05-28 12:13:19,699 - INFO - \U0001f4e5 Starting data extraction...
2025-05-28 12:13:19,724 - INFO - \u2705 Data extracted successfully
2025-05-28 12:13:19,724 - INFO - \U0001f527 Starting data transformation...
2025-05-28 12:13:19,739 - INFO - \u2705 Data transformed successfully
2025-05-28 12:13:19,739 - INFO - \U0001f4be Starting data load into database...
2025-05-28 12:13:19,739 - ERROR - \u274c Unexpected error occurred: load_data() missing 1 required positional argument: 'table_name'
2025-05-28 12:13:19,740 - ERROR - Traceback (most recent call last):
  File "C:\Users\Branton\Documents\Flatiron\Projects\Data-Pipeline\run_pipeline.py", line 26, in run_pipeline
    load_data(transformed_df)
TypeError: load_data() missing 1 required positional argument: 'table_name'

2025-05-28 12:54:46,857 INFO: Data extracted successfully.
2025-05-28 12:54:46,862 INFO: Data transformed successfully.
2025-05-28 12:54:48,499 ERROR: Failed to load data: (psycopg2.OperationalError) connection to server at "localhost" (::1), port 5432 failed: FATAL:  database "data-pipeline" does not exist

(Background on this error at: https://sqlalche.me/e/20/e3q8)
2025-05-28 12:54:48,499 ERROR: Pipeline failed: (psycopg2.OperationalError) connection to server at "localhost" (::1), port 5432 failed: FATAL:  database "data-pipeline" does not exist

(Background on this error at: https://sqlalche.me/e/20/e3q8)
2025-05-28 12:56:13,891:INFO:\U0001f680 Starting pipeline...
2025-05-28 12:56:13,922:ERROR:Failed to extract data: [Errno 2] No such file or directory: 'C:\\Users\\Branton\\Documents\\Flatiron\\Projects\\Data-Pipeline\\airtravel.csv'
2025-05-28 12:56:13,922:ERROR:\u274c Pipeline execution failed.
Traceback (most recent call last):
  File "C:\Users\Branton\Documents\Flatiron\Projects\Data-Pipeline\run_pipeline.py", line 14, in <module>
    raw_df = extract_data()
             ^^^^^^^^^^^^^^
  File "C:\Users\Branton\Documents\Flatiron\Projects\Data-Pipeline\scripts\extract.py", line 7, in extract_data
    df = pd.read_csv(file_path)
         ^^^^^^^^^^^^^^^^^^^^^^
  File "C:\Users\Branton\Documents\Flatiron\Projects\Data-Pipeline\venv\Lib\site-packages\pandas\io\parsers\readers.py", line 1026, in read_csv
    return _read(filepath_or_buffer, kwds)
           ^^^^^^^^^^^^^^^^^^^^^^^^^^^^^^^
  File "C:\Users\Branton\Documents\Flatiron\Projects\Data-Pipeline\venv\Lib\site-packages\pandas\io\parsers\readers.py", line 620, in _read
    parser = TextFileReader(filepath_or_buffer, **kwds)
             ^^^^^^^^^^^^^^^^^^^^^^^^^^^^^^^^^^^^^^^^^^
  File "C:\Users\Branton\Documents\Flatiron\Projects\Data-Pipeline\venv\Lib\site-packages\pandas\io\parsers\readers.py", line 1620, in __init__
    self._engine = self._make_engine(f, self.engine)
                   ^^^^^^^^^^^^^^^^^^^^^^^^^^^^^^^^^
  File "C:\Users\Branton\Documents\Flatiron\Projects\Data-Pipeline\venv\Lib\site-packages\pandas\io\parsers\readers.py", line 1880, in _make_engine
    self.handles = get_handle(
                   ^^^^^^^^^^^
  File "C:\Users\Branton\Documents\Flatiron\Projects\Data-Pipeline\venv\Lib\site-packages\pandas\io\common.py", line 873, in get_handle
    handle = open(
             ^^^^^
FileNotFoundError: [Errno 2] No such file or directory: 'C:\\Users\\Branton\\Documents\\Flatiron\\Projects\\Data-Pipeline\\airtravel.csv'
2025-05-28 12:56:49,152:INFO:\U0001f680 Starting pipeline...
2025-05-28 12:56:49,156:INFO:Data extracted successfully.
2025-05-28 12:56:49,158:INFO:Data transformed successfully.
2025-05-28 12:56:49,281:ERROR:Failed to load data: (psycopg2.OperationalError) connection to server at "localhost" (::1), port 5432 failed: FATAL:  database "data-pipeline" does not exist

(Background on this error at: https://sqlalche.me/e/20/e3q8)
2025-05-28 12:56:49,282:ERROR:\u274c Pipeline execution failed.
Traceback (most recent call last):
  File "C:\Users\Branton\Documents\Flatiron\Projects\Data-Pipeline\venv\Lib\site-packages\sqlalchemy\engine\base.py", line 145, in __init__
    self._dbapi_connection = engine.raw_connection()
                             ^^^^^^^^^^^^^^^^^^^^^^^
  File "C:\Users\Branton\Documents\Flatiron\Projects\Data-Pipeline\venv\Lib\site-packages\sqlalchemy\engine\base.py", line 3297, in raw_connection
    return self.pool.connect()
           ^^^^^^^^^^^^^^^^^^^
  File "C:\Users\Branton\Documents\Flatiron\Projects\Data-Pipeline\venv\Lib\site-packages\sqlalchemy\pool\base.py", line 449, in connect
    return _ConnectionFairy._checkout(self)
           ^^^^^^^^^^^^^^^^^^^^^^^^^^^^^^^^
  File "C:\Users\Branton\Documents\Flatiron\Projects\Data-Pipeline\venv\Lib\site-packages\sqlalchemy\pool\base.py", line 1264, in _checkout
    fairy = _ConnectionRecord.checkout(pool)
            ^^^^^^^^^^^^^^^^^^^^^^^^^^^^^^^^
  File "C:\Users\Branton\Documents\Flatiron\Projects\Data-Pipeline\venv\Lib\site-packages\sqlalchemy\pool\base.py", line 713, in checkout
    rec = pool._do_get()
          ^^^^^^^^^^^^^^
  File "C:\Users\Branton\Documents\Flatiron\Projects\Data-Pipeline\venv\Lib\site-packages\sqlalchemy\pool\impl.py", line 179, in _do_get
    with util.safe_reraise():
         ^^^^^^^^^^^^^^^^^^^
  File "C:\Users\Branton\Documents\Flatiron\Projects\Data-Pipeline\venv\Lib\site-packages\sqlalchemy\util\langhelpers.py", line 224, in __exit__
    raise exc_value.with_traceback(exc_tb)
  File "C:\Users\Branton\Documents\Flatiron\Projects\Data-Pipeline\venv\Lib\site-packages\sqlalchemy\pool\impl.py", line 177, in _do_get
    return self._create_connection()
           ^^^^^^^^^^^^^^^^^^^^^^^^^
  File "C:\Users\Branton\Documents\Flatiron\Projects\Data-Pipeline\venv\Lib\site-packages\sqlalchemy\pool\base.py", line 390, in _create_connection
    return _ConnectionRecord(self)
           ^^^^^^^^^^^^^^^^^^^^^^^
  File "C:\Users\Branton\Documents\Flatiron\Projects\Data-Pipeline\venv\Lib\site-packages\sqlalchemy\pool\base.py", line 675, in __init__
    self.__connect()
  File "C:\Users\Branton\Documents\Flatiron\Projects\Data-Pipeline\venv\Lib\site-packages\sqlalchemy\pool\base.py", line 901, in __connect
    with util.safe_reraise():
         ^^^^^^^^^^^^^^^^^^^
  File "C:\Users\Branton\Documents\Flatiron\Projects\Data-Pipeline\venv\Lib\site-packages\sqlalchemy\util\langhelpers.py", line 224, in __exit__
    raise exc_value.with_traceback(exc_tb)
  File "C:\Users\Branton\Documents\Flatiron\Projects\Data-Pipeline\venv\Lib\site-packages\sqlalchemy\pool\base.py", line 897, in __connect
    self.dbapi_connection = connection = pool._invoke_creator(self)
                                         ^^^^^^^^^^^^^^^^^^^^^^^^^^
  File "C:\Users\Branton\Documents\Flatiron\Projects\Data-Pipeline\venv\Lib\site-packages\sqlalchemy\engine\create.py", line 646, in connect
    return dialect.connect(*cargs, **cparams)
           ^^^^^^^^^^^^^^^^^^^^^^^^^^^^^^^^^^
  File "C:\Users\Branton\Documents\Flatiron\Projects\Data-Pipeline\venv\Lib\site-packages\sqlalchemy\engine\default.py", line 625, in connect
    return self.loaded_dbapi.connect(*cargs, **cparams)  # type: ignore[no-any-return]  # NOQA: E501
           ^^^^^^^^^^^^^^^^^^^^^^^^^^^^^^^^^^^^^^^^^^^^
  File "C:\Users\Branton\Documents\Flatiron\Projects\Data-Pipeline\venv\Lib\site-packages\psycopg2\__init__.py", line 122, in connect
    conn = _connect(dsn, connection_factory=connection_factory, **kwasync)
           ^^^^^^^^^^^^^^^^^^^^^^^^^^^^^^^^^^^^^^^^^^^^^^^^^^^^^^^^^^^^^^^
psycopg2.OperationalError: connection to server at "localhost" (::1), port 5432 failed: FATAL:  database "data-pipeline" does not exist


The above exception was the direct cause of the following exception:

Traceback (most recent call last):
  File "C:\Users\Branton\Documents\Flatiron\Projects\Data-Pipeline\run_pipeline.py", line 22, in <module>
    load_data(clean_df, table_name="airtravel_data")
  File "C:\Users\Branton\Documents\Flatiron\Projects\Data-Pipeline\scripts\load.py", line 11, in load_data
    df.to_sql(table_name, engine, if_exists='replace', index=False)
  File "C:\Users\Branton\Documents\Flatiron\Projects\Data-Pipeline\venv\Lib\site-packages\pandas\util\_decorators.py", line 333, in wrapper
    return func(*args, **kwargs)
           ^^^^^^^^^^^^^^^^^^^^^
  File "C:\Users\Branton\Documents\Flatiron\Projects\Data-Pipeline\venv\Lib\site-packages\pandas\core\generic.py", line 3087, in to_sql
    return sql.to_sql(
           ^^^^^^^^^^^
  File "C:\Users\Branton\Documents\Flatiron\Projects\Data-Pipeline\venv\Lib\site-packages\pandas\io\sql.py", line 841, in to_sql
    with pandasSQL_builder(con, schema=schema, need_transaction=True) as pandas_sql:
         ^^^^^^^^^^^^^^^^^^^^^^^^^^^^^^^^^^^^^^^^^^^^^^^^^^^^^^^^^^^^
  File "C:\Users\Branton\Documents\Flatiron\Projects\Data-Pipeline\venv\Lib\site-packages\pandas\io\sql.py", line 906, in pandasSQL_builder
    return SQLDatabase(con, schema, need_transaction)
           ^^^^^^^^^^^^^^^^^^^^^^^^^^^^^^^^^^^^^^^^^^
  File "C:\Users\Branton\Documents\Flatiron\Projects\Data-Pipeline\venv\Lib\site-packages\pandas\io\sql.py", line 1636, in __init__
    con = self.exit_stack.enter_context(con.connect())
                                        ^^^^^^^^^^^^^
  File "C:\Users\Branton\Documents\Flatiron\Projects\Data-Pipeline\venv\Lib\site-packages\sqlalchemy\engine\base.py", line 3273, in connect
    return self._connection_cls(self)
           ^^^^^^^^^^^^^^^^^^^^^^^^^^
  File "C:\Users\Branton\Documents\Flatiron\Projects\Data-Pipeline\venv\Lib\site-packages\sqlalchemy\engine\base.py", line 147, in __init__
    Connection._handle_dbapi_exception_noconnection(
  File "C:\Users\Branton\Documents\Flatiron\Projects\Data-Pipeline\venv\Lib\site-packages\sqlalchemy\engine\base.py", line 2436, in _handle_dbapi_exception_noconnection
    raise sqlalchemy_exception.with_traceback(exc_info[2]) from e
  File "C:\Users\Branton\Documents\Flatiron\Projects\Data-Pipeline\venv\Lib\site-packages\sqlalchemy\engine\base.py", line 145, in __init__
    self._dbapi_connection = engine.raw_connection()
                             ^^^^^^^^^^^^^^^^^^^^^^^
  File "C:\Users\Branton\Documents\Flatiron\Projects\Data-Pipeline\venv\Lib\site-packages\sqlalchemy\engine\base.py", line 3297, in raw_connection
    return self.pool.connect()
           ^^^^^^^^^^^^^^^^^^^
  File "C:\Users\Branton\Documents\Flatiron\Projects\Data-Pipeline\venv\Lib\site-packages\sqlalchemy\pool\base.py", line 449, in connect
    return _ConnectionFairy._checkout(self)
           ^^^^^^^^^^^^^^^^^^^^^^^^^^^^^^^^
  File "C:\Users\Branton\Documents\Flatiron\Projects\Data-Pipeline\venv\Lib\site-packages\sqlalchemy\pool\base.py", line 1264, in _checkout
    fairy = _ConnectionRecord.checkout(pool)
            ^^^^^^^^^^^^^^^^^^^^^^^^^^^^^^^^
  File "C:\Users\Branton\Documents\Flatiron\Projects\Data-Pipeline\venv\Lib\site-packages\sqlalchemy\pool\base.py", line 713, in checkout
    rec = pool._do_get()
          ^^^^^^^^^^^^^^
  File "C:\Users\Branton\Documents\Flatiron\Projects\Data-Pipeline\venv\Lib\site-packages\sqlalchemy\pool\impl.py", line 179, in _do_get
    with util.safe_reraise():
         ^^^^^^^^^^^^^^^^^^^
  File "C:\Users\Branton\Documents\Flatiron\Projects\Data-Pipeline\venv\Lib\site-packages\sqlalchemy\util\langhelpers.py", line 224, in __exit__
    raise exc_value.with_traceback(exc_tb)
  File "C:\Users\Branton\Documents\Flatiron\Projects\Data-Pipeline\venv\Lib\site-packages\sqlalchemy\pool\impl.py", line 177, in _do_get
    return self._create_connection()
           ^^^^^^^^^^^^^^^^^^^^^^^^^
  File "C:\Users\Branton\Documents\Flatiron\Projects\Data-Pipeline\venv\Lib\site-packages\sqlalchemy\pool\base.py", line 390, in _create_connection
    return _ConnectionRecord(self)
           ^^^^^^^^^^^^^^^^^^^^^^^
  File "C:\Users\Branton\Documents\Flatiron\Projects\Data-Pipeline\venv\Lib\site-packages\sqlalchemy\pool\base.py", line 675, in __init__
    self.__connect()
  File "C:\Users\Branton\Documents\Flatiron\Projects\Data-Pipeline\venv\Lib\site-packages\sqlalchemy\pool\base.py", line 901, in __connect
    with util.safe_reraise():
         ^^^^^^^^^^^^^^^^^^^
  File "C:\Users\Branton\Documents\Flatiron\Projects\Data-Pipeline\venv\Lib\site-packages\sqlalchemy\util\langhelpers.py", line 224, in __exit__
    raise exc_value.with_traceback(exc_tb)
  File "C:\Users\Branton\Documents\Flatiron\Projects\Data-Pipeline\venv\Lib\site-packages\sqlalchemy\pool\base.py", line 897, in __connect
    self.dbapi_connection = connection = pool._invoke_creator(self)
                                         ^^^^^^^^^^^^^^^^^^^^^^^^^^
  File "C:\Users\Branton\Documents\Flatiron\Projects\Data-Pipeline\venv\Lib\site-packages\sqlalchemy\engine\create.py", line 646, in connect
    return dialect.connect(*cargs, **cparams)
           ^^^^^^^^^^^^^^^^^^^^^^^^^^^^^^^^^^
  File "C:\Users\Branton\Documents\Flatiron\Projects\Data-Pipeline\venv\Lib\site-packages\sqlalchemy\engine\default.py", line 625, in connect
    return self.loaded_dbapi.connect(*cargs, **cparams)  # type: ignore[no-any-return]  # NOQA: E501
           ^^^^^^^^^^^^^^^^^^^^^^^^^^^^^^^^^^^^^^^^^^^^
  File "C:\Users\Branton\Documents\Flatiron\Projects\Data-Pipeline\venv\Lib\site-packages\psycopg2\__init__.py", line 122, in connect
    conn = _connect(dsn, connection_factory=connection_factory, **kwasync)
           ^^^^^^^^^^^^^^^^^^^^^^^^^^^^^^^^^^^^^^^^^^^^^^^^^^^^^^^^^^^^^^^
sqlalchemy.exc.OperationalError: (psycopg2.OperationalError) connection to server at "localhost" (::1), port 5432 failed: FATAL:  database "data-pipeline" does not exist

(Background on this error at: https://sqlalche.me/e/20/e3q8)
2025-05-28 12:59:39,370:INFO:\U0001f680 Starting pipeline...
2025-05-28 12:59:39,373:INFO:Data extracted successfully.
2025-05-28 12:59:39,377:INFO:Data transformed successfully.
2025-05-28 12:59:41,060:INFO:Data loaded successfully.
2025-05-28 12:59:41,060:INFO:\u2705 Pipeline executed successfully.
2025-05-29 10:41:41,661:INFO:\U0001f680 Starting pipeline...
2025-05-29 10:41:41,688:INFO:Data extracted successfully.
2025-05-29 10:41:41,688:ERROR:\u274c Pipeline execution failed.
Traceback (most recent call last):
  File "C:\Users\Branton\Documents\Flatiron\Projects\Data-Pipeline\run_pipeline.py", line 17, in <module>
    clean_df = transform_data(raw_df)
               ^^^^^^^^^^^^^^
NameError: name 'transform_data' is not defined
2025-05-29 10:43:05,754:INFO:\U0001f680 Starting pipeline...
2025-05-29 10:43:05,754:ERROR:\u274c Pipeline execution failed.
Traceback (most recent call last):
  File "c:\Users\Branton\Documents\Flatiron\Projects\Data-Pipeline\run_pipeline.py", line 13, in <module>
    print("\U0001f4e5 Extracting data...")
  File "C:\Python312\Lib\encodings\cp1252.py", line 19, in encode
    return codecs.charmap_encode(input,self.errors,encoding_table)[0]
           ^^^^^^^^^^^^^^^^^^^^^^^^^^^^^^^^^^^^^^^^^^^^^^^^^^^^^^^
UnicodeEncodeError: 'charmap' codec can't encode character '\U0001f4e5' in position 0: character maps to <undefined>
2025-05-29 11:08:23,200:INFO:\U0001f680 Starting pipeline...
2025-05-29 11:08:23,228:INFO:Data extracted successfully.
2025-05-29 11:08:23,229:ERROR:\u274c Pipeline execution failed.
Traceback (most recent call last):
  File "C:\Users\Branton\Documents\Flatiron\Projects\Data-Pipeline\run_pipeline.py", line 17, in <module>
    clean_df = transform_airtravel_data(raw_df)
               ^^^^^^^^^^^^^^^^^^^^^^^^^^^^^^^^
TypeError: transform_airtravel_data() takes 0 positional arguments but 1 was given
2025-05-29 11:12:20,113:INFO:\U0001f680 Starting pipeline...
2025-05-29 11:12:20,125:INFO:Data extracted successfully.
2025-05-29 11:12:20,125:ERROR:\u274c Pipeline execution failed.
Traceback (most recent call last):
  File "C:\Users\Branton\Documents\Flatiron\Projects\Data-Pipeline\run_pipeline.py", line 17, in <module>
    clean_df = transform_airtravel_data(raw)
                                        ^^^
NameError: name 'raw' is not defined
2025-05-29 11:20:07,187:INFO:\U0001f680 Starting pipeline...
2025-05-29 11:20:07,193:INFO:Data extracted successfully.
2025-05-29 11:20:09,294:INFO:Data loaded successfully.
2025-05-29 11:20:09,294:INFO:\u2705 Pipeline executed successfully.
